{
  "comments": [
    {
      "key": {
        "uuid": "e6f1f3d8_6a796530",
        "filename": "test/lvol/test_cases.py",
        "patchSetId": 44
      },
      "lineNbr": 297,
      "author": {
        "id": 1011256
      },
      "writtenOn": "2017-09-28T08:02:28Z",
      "side": 1,
      "message": "in some tests you return \"fail_count\" at the end of test, in here you return 0 - please be consistent and use one approach",
      "range": {
        "startLine": 297,
        "startChar": 8,
        "endLine": 297,
        "endChar": 16
      },
      "revId": "08b5f6de5d59d6291fa131df3b197aec42f2c01d",
      "serverId": "d5d70762-12d0-45a1-890d-524b12d3f735",
      "unresolved": false
    },
    {
      "key": {
        "uuid": "2619b676_60a1d82e",
        "filename": "test/lvol/test_cases.py",
        "patchSetId": 44
      },
      "lineNbr": 348,
      "author": {
        "id": 1011256
      },
      "writtenOn": "2017-09-28T08:02:28Z",
      "side": 1,
      "message": "as in first comment - any chance on using fail_count instead of return 1?",
      "range": {
        "startLine": 348,
        "startChar": 23,
        "endLine": 348,
        "endChar": 31
      },
      "revId": "08b5f6de5d59d6291fa131df3b197aec42f2c01d",
      "serverId": "d5d70762-12d0-45a1-890d-524b12d3f735",
      "unresolved": false
    }
  ]
}